Workbook

Sheet データ
A1: 日付 | B1: メンバー | C1: 平日フラグ | D1: 架電数 | E1: 接触数(接続) | F1: 60秒以上通話数 | G1: 接続通話秒計 | H1: 総通話秒計(発着信) | I1: 着信数 | J1: 着信不在数 | K1: 初回架電時刻 | L1: 最終終話時刻 | M1: 架電間隔計(秒) | N1: 架電間隔件数 | O1: 30分超アイドル回数 | P1: ユニーク相手番号数 | Q1: 再架電件数(2回目以降) | R1: 月 | S1: 稼働時間(h) | T1: 平均架電間隔(分) | U1: 平均通話時間(秒) | V1: 接続率
A2: 46237 | B2: 篠﨑 悠 | C2: 1 | D2: 33 | E2: 28 | F2: 22 | G2: 7937 | H2: 7937 | I2: 6 | J2: 6 | K2: 0.487847 | L2: 0.782037 | M2: 17183 | N2: 33 | O2: 3 | P2: 29 | Q2: 4 | R2: =TEXT(A2,"yyyy-mm") -> 2026-08 | S2: =IF(K2="","",(L2-K2)*24) -> 7.06056 | T2: =IF(N2=0,"",M2/N2/60) -> 8.6782828 | U2: =IF(E2=0,"",G2/E2) -> 283.46429 | V2: =IF(D2=0,"",E2/D2) -> 0.84848485
A3: 46238 | B3: 篠﨑 悠 | C3: 1 | D3: 32 | E3: 28 | F3: 15 | G3: 5284 | H3: 7046 | I3: 8 | J3: 3 | K3: 0.430289 | L3: 0.826921 | M3: 10329 | N3: 30 | O3: 3 | P3: 26 | Q3: 9 | R3: =TEXT(A3,"yyyy-mm") -> 2026-08 | S3: =IF(K3="","",(L3-K3)*24) -> 9.519168 | T3: =IF(N3=0,"",M3/N3/60) -> 5.7383333 | U3: =IF(E3=0,"",G3/E3) -> 188.71429 | V3: =IF(D3=0,"",E3/D3) -> 0.875
A4: 46239 | B4: 篠﨑 悠 | C4: 1 | D4: 47 | E4: 42 | F4: 19 | G4: 8021 | H4: 8841 | I4: 8 | J4: 5 | K4: 0.427199 | L4: 0.762106 | M4: 13793 | N4: 46 | O4: 2 | P4: 45 | Q4: 10 | R4: =TEXT(A4,"yyyy-mm") -> 2026-08 | S4: =IF(K4="","",(L4-K4)*24) -> 8.037768 | T4: =IF(N4=0,"",M4/N4/60) -> 4.9974638 | U4: =IF(E4=0,"",G4/E4) -> 190.97619 | V4: =IF(D4=0,"",E4/D4) -> 0.89361702
A5: 46240 | B5: 篠﨑 悠 | C5: 1 | D5: 42 | E5: 35 | F5: 23 | G5: 6838 | H5: 7897 | I5: 14 | J5: 11 | K5: 0.458912 | L5: 0.778657 | M5: 15084 | N5: 41 | O5: 3 | P5: 36 | Q5: 13 | R5: =TEXT(A5,"yyyy-mm") -> 2026-08 | S5: =IF(K5="","",(L5-K5)*24) -> 7.67388 | T5: =IF(N5=0,"",M5/N5/60) -> 6.1317073 | U5: =IF(E5=0,"",G5/E5) -> 195.37143 | V5: =IF(D5=0,"",E5/D5) -> 0.83333333
A6: 46241 | B6: 篠﨑 悠 | C6: 1 | D6: 55 | E6: 43 | F6: 24 | G6: 7484 | H6: 7911 | I6: 12 | J6: 11 | K6: 0.439491 | L6: 0.808449 | M6: 20161 | N6: 55 | O6: 2 | P6: 46 | Q6: 23 | R6: =TEXT(A6,"yyyy-mm") -> 2026-08 | S6: =IF(K6="","",(L6-K6)*24) -> 8.854992 | T6: =IF(N6=0,"",M6/N6/60) -> 6.1093939 | U6: =IF(E6=0,"",G6/E6) -> 174.04651 | V6: =IF(D6=0,"",E6/D6) -> 0.78181818
A7: 46242 | B7: 篠﨑 悠 | C7: 0 | D7: 0 | E7: 0 | F7: 0 | G7: 0 | H7: 0 | I7: 2 | J7: 2 | M7: 0 | N7: 0 | O7: 0 | P7: 0 | Q7: 0 | R7: =TEXT(A7,"yyyy-mm") -> 2026-08 | S7: =IF(K7="","",(L7-K7)*24) | T7: =IF(N7=0,"",M7/N7/60) | U7: =IF(E7=0,"",G7/E7) | V7: =IF(D7=0,"",E7/D7)
A8: 46244 | B8: 篠﨑 悠 | C8: 1 | D8: 52 | E8: 40 | F8: 22 | G8: 6464 | H8: 8737 | I8: 5 | J8: 1 | K8: 0.460718 | L8: 0.815648 | M8: 16102 | N8: 50 | O8: 3 | P8: 49 | Q8: 17 | R8: =TEXT(A8,"yyyy-mm") -> 2026-08 | S8: =IF(K8="","",(L8-K8)*24) -> 8.51832 | T8: =IF(N8=0,"",M8/N8/60) -> 5.3673333 | U8: =IF(E8=0,"",G8/E8) -> 161.6 | V8: =IF(D8=0,"",E8/D8) -> 0.76923077
A9: 46245 | B9: 篠﨑 悠 | C9: 1 | D9: 0 | E9: 0 | F9: 0 | G9: 0 | H9: 0 | I9: 1 | J9: 1 | M9: 0 | N9: 0 | O9: 0 | P9: 0 | Q9: 0 | R9: =TEXT(A9,"yyyy-mm") -> 2026-08 | S9: =IF(K9="","",(L9-K9)*24) | T9: =IF(N9=0,"",M9/N9/60) | U9: =IF(E9=0,"",G9/E9) | V9: =IF(D9=0,"",E9/D9)
A10: 46246 | B10: 篠﨑 悠 | C10: 1 | D10: 65 | E10: 49 | F10: 22 | G10: 8911 | H10: 9966 | I10: 10 | J10: 5 | K10: 0.431042 | L10: 0.751493 | M10: 10898 | N10: 64 | O10: 1 | P10: 58 | Q10: 35 | R10: =TEXT(A10,"yyyy-mm") -> 2026-08 | S10: =IF(K10="","",(L10-K10)*24) -> 7.690824 | T10: =IF(N10=0,"",M10/N10/60) -> 2.8380208 | U10: =IF(E10=0,"",G10/E10) -> 181.85714 | V10: =IF(D10=0,"",E10/D10) -> 0.75384615
A11: 46247 | B11: 篠﨑 悠 | C11: 1 | D11: 0 | E11: 0 | F11: 0 | G11: 0 | H11: 0 | I11: 6 | J11: 6 | M11: 0 | N11: 0 | O11: 0 | P11: 0 | Q11: 0 | R11: =TEXT(A11,"yyyy-mm") -> 2026-08 | S11: =IF(K11="","",(L11-K11)*24) | T11: =IF(N11=0,"",M11/N11/60) | U11: =IF(E11=0,"",G11/E11) | V11: =IF(D11=0,"",E11/D11)
A12: 46249 | B12: 篠﨑 悠 | C12: 0 | D12: 0 | E12: 0 | F12: 0 | G12: 0 | H12: 0 | I12: 1 | J12: 1 | M12: 0 | N12: 0 | O12: 0 | P12: 0 | Q12: 0 | R12: =TEXT(A12,"yyyy-mm") -> 2026-08 | S12: =IF(K12="","",(L12-K12)*24) | T12: =IF(N12=0,"",M12/N12/60) | U12: =IF(E12=0,"",G12/E12) | V12: =IF(D12=0,"",E12/D12)
A13: 46250 | B13: 篠﨑 悠 | C13: 0 | D13: 0 | E13: 0 | F13: 0 | G13: 0 | H13: 0 | I13: 1 | J13: 1 | M13: 0 | N13: 0 | O13: 0 | P13: 0 | Q13: 0 | R13: =TEXT(A13,"yyyy-mm") -> 2026-08 | S13: =IF(K13="","",(L13-K13)*24) | T13: =IF(N13=0,"",M13/N13/60) | U13: =IF(E13=0,"",G13/E13) | V13: =IF(D13=0,"",E13/D13)
A14: 46251 | B14: 篠﨑 悠 | C14: 1 | D14: 0 | E14: 0 | F14: 0 | G14: 0 | H14: 0 | I14: 10 | J14: 10 | M14: 0 | N14: 0 | O14: 0 | P14: 0 | Q14: 0 | R14: =TEXT(A14,"yyyy-mm") -> 2026-08 | S14: =IF(K14="","",(L14-K14)*24) | T14: =IF(N14=0,"",M14/N14/60) | U14: =IF(E14=0,"",G14/E14) | V14: =IF(D14=0,"",E14/D14)
A15: 46252 | B15: 篠﨑 悠 | C15: 1 | D15: 40 | E15: 32 | F15: 21 | G15: 8091 | H15: 9370 | I15: 26 | J15: 21 | K15: 0.437512 | L15: 0.796574 | M15: 13385 | N15: 39 | O15: 1 | P15: 35 | Q15: 18 | R15: =TEXT(A15,"yyyy-mm") -> 2026-08 | S15: =IF(K15="","",(L15-K15)*24) -> 8.617488 | T15: =IF(N15=0,"",M15/N15/60) -> 5.7200855 | U15: =IF(E15=0,"",G15/E15) -> 252.84375 | V15: =IF(D15=0,"",E15/D15) -> 0.8
A16: 46253 | B16: 篠﨑 悠 | C16: 1 | D16: 48 | E16: 40 | F16: 17 | G16: 6516 | H16: 8370 | I16: 20 | J16: 11 | K16: 0.405428 | L16: 0.747951 | M16: 14933 | N16: 47 | O16: 1 | P16: 45 | Q16: 24 | R16: =TEXT(A16,"yyyy-mm") -> 2026-08 | S16: =IF(K16="","",(L16-K16)*24) -> 8.220552 | T16: =IF(N16=0,"",M16/N16/60) -> 5.2953901 | U16: =IF(E16=0,"",G16/E16) -> 162.9 | V16: =IF(D16=0,"",E16/D16) -> 0.83333333
A17: 46254 | B17: 篠﨑 悠 | C17: 1 | D17: 46 | E17: 43 | F17: 20 | G17: 5969 | H17: 6339 | I17: 4 | J17: 2 | K17: 0.44934 | L17: 0.729317 | M17: 11793 | N17: 44 | O17: 2 | P17: 42 | Q17: 22 | R17: =TEXT(A17,"yyyy-mm") -> 2026-08 | S17: =IF(K17="","",(L17-K17)*24) -> 6.719448 | T17: =IF(N17=0,"",M17/N17/60) -> 4.4670455 | U17: =IF(E17=0,"",G17/E17) -> 138.81395 | V17: =IF(D17=0,"",E17/D17) -> 0.93478261
A18: 46255 | B18: 篠﨑 悠 | C18: 1 | D18: 51 | E18: 44 | F18: 21 | G18: 6151 | H18: 8087 | I18: 8 | J18: 4 | K18: 0.430937 | L18: 0.727975 | M18: 13776 | N18: 50 | O18: 2 | P18: 48 | Q18: 29 | R18: =TEXT(A18,"yyyy-mm") -> 2026-08 | S18: =IF(K18="","",(L18-K18)*24) -> 7.128912 | T18: =IF(N18=0,"",M18/N18/60) -> 4.592 | U18: =IF(E18=0,"",G18/E18) -> 139.79545 | V18: =IF(D18=0,"",E18/D18) -> 0.8627451
A19: 46256 | B19: 篠﨑 悠 | C19: 0 | D19: 0 | E19: 0 | F19: 0 | G19: 0 | H19: 0 | I19: 1 | J19: 1 | M19: 0 | N19: 0 | O19: 0 | P19: 0 | Q19: 0 | R19: =TEXT(A19,"yyyy-mm") -> 2026-08 | S19: =IF(K19="","",(L19-K19)*24) | T19: =IF(N19=0,"",M19/N19/60) | U19: =IF(E19=0,"",G19/E19) | V19: =IF(D19=0,"",E19/D19)
A20: 46257 | B20: 篠﨑 悠 | C20: 0 | D20: 0 | E20: 0 | F20: 0 | G20: 0 | H20: 0 | I20: 1 | J20: 1 | M20: 0 | N20: 0 | O20: 0 | P20: 0 | Q20: 0 | R20: =TEXT(A20,"yyyy-mm") -> 2026-08 | S20: =IF(K20="","",(L20-K20)*24) | T20: =IF(N20=0,"",M20/N20/60) | U20: =IF(E20=0,"",G20/E20) | V20: =IF(D20=0,"",E20/D20)
A21: 46258 | B21: 篠﨑 悠 | C21: 1 | D21: 41 | E21: 31 | F21: 12 | G21: 5338 | H21: 7571 | I21: 8 | J21: 4 | K21: 0.471632 | L21: 0.795405 | M21: 13299 | N21: 40 | O21: 2 | P21: 39 | Q21: 24 | R21: =TEXT(A21,"yyyy-mm") -> 2026-08 | S21: =IF(K21="","",(L21-K21)*24) -> 7.770552 | T21: =IF(N21=0,"",M21/N21/60) -> 5.54125 | U21: =IF(E21=0,"",G21/E21) -> 172.19355 | V21: =IF(D21=0,"",E21/D21) -> 0.75609756
A22: 46259 | B22: 篠﨑 悠 | C22: 1 | D22: 62 | E22: 46 | F22: 18 | G22: 7244 | H22: 7313 | I22: 9 | J22: 7 | K22: 0.427639 | L22: 0.826227 | M22: 14309 | N22: 60 | O22: 2 | P22: 56 | Q22: 24 | R22: =TEXT(A22,"yyyy-mm") -> 2026-08 | S22: =IF(K22="","",(L22-K22)*24) -> 9.566112 | T22: =IF(N22=0,"",M22/N22/60) -> 3.9747222 | U22: =IF(E22=0,"",G22/E22) -> 157.47826 | V22: =IF(D22=0,"",E22/D22) -> 0.74193548
A23: 46260 | B23: 篠﨑 悠 | C23: 1 | D23: 21 | E23: 20 | F23: 17 | G23: 3826 | H23: 5002 | I23: 8 | J23: 4 | K23: 0.434838 | L23: 0.736377 | M23: 7891 | N23: 19 | O23: 3 | P23: 21 | Q23: 13 | R23: =TEXT(A23,"yyyy-mm") -> 2026-08 | S23: =IF(K23="","",(L23-K23)*24) -> 7.236936 | T23: =IF(N23=0,"",M23/N23/60) -> 6.9219298 | U23: =IF(E23=0,"",G23/E23) -> 191.3 | V23: =IF(D23=0,"",E23/D23) -> 0.95238095
A24: 46261 | B24: 篠﨑 悠 | C24: 1 | D24: 22 | E24: 19 | F24: 7 | G24: 2548 | H24: 4640 | I24: 9 | J24: 5 | K24: 0.444641 | L24: 0.704572 | M24: 6123 | N24: 19 | O24: 3 | P24: 19 | Q24: 8 | R24: =TEXT(A24,"yyyy-mm") -> 2026-08 | S24: =IF(K24="","",(L24-K24)*24) -> 6.238344 | T24: =IF(N24=0,"",M24/N24/60) -> 5.3710526 | U24: =IF(E24=0,"",G24/E24) -> 134.10526 | V24: =IF(D24=0,"",E24/D24) -> 0.86363636
A25: 46262 | B25: 篠﨑 悠 | C25: 1 | D25: 31 | E25: 30 | F25: 15 | G25: 7553 | H25: 9772 | I25: 12 | J25: 6 | K25: 0.40684 | L25: 0.757755 | M25: 12995 | N25: 31 | O25: 2 | P25: 26 | Q25: 15 | R25: =TEXT(A25,"yyyy-mm") -> 2026-08 | S25: =IF(K25="","",(L25-K25)*24) -> 8.42196 | T25: =IF(N25=0,"",M25/N25/60) -> 6.9865591 | U25: =IF(E25=0,"",G25/E25) -> 251.76667 | V25: =IF(D25=0,"",E25/D25) -> 0.96774194
A26: 46263 | B26: 篠﨑 悠 | C26: 0 | D26: 0 | E26: 0 | F26: 0 | G26: 0 | H26: 0 | I26: 2 | J26: 2 | M26: 0 | N26: 0 | O26: 0 | P26: 0 | Q26: 0 | R26: =TEXT(A26,"yyyy-mm") -> 2026-08 | S26: =IF(K26="","",(L26-K26)*24) | T26: =IF(N26=0,"",M26/N26/60) | U26: =IF(E26=0,"",G26/E26) | V26: =IF(D26=0,"",E26/D26)
A27: 46264 | B27: 篠﨑 悠 | C27: 0 | D27: 0 | E27: 0 | F27: 0 | G27: 0 | H27: 0 | I27: 1 | J27: 1 | M27: 0 | N27: 0 | O27: 0 | P27: 0 | Q27: 0 | R27: =TEXT(A27,"yyyy-mm") -> 2026-08 | S27: =IF(K27="","",(L27-K27)*24) | T27: =IF(N27=0,"",M27/N27/60) | U27: =IF(E27=0,"",G27/E27) | V27: =IF(D27=0,"",E27/D27)
A28: 46265 | B28: 篠﨑 悠 | C28: 1 | D28: 33 | E28: 32 | F28: 22 | G28: 7401 | H28: 9515 | I28: 17 | J28: 9 | K28: 0.439896 | L28: 0.773623 | M28: 11865 | N28: 32 | O28: 1 | P28: 27 | Q28: 21 | R28: =TEXT(A28,"yyyy-mm") -> 2026-08 | S28: =IF(K28="","",(L28-K28)*24) -> 8.009448 | T28: =IF(N28=0,"",M28/N28/60) -> 6.1796875 | U28: =IF(E28=0,"",G28/E28) -> 231.28125 | V28: =IF(D28=0,"",E28/D28) -> 0.96969697
A29: 46266 | B29: 篠﨑 悠 | C29: 1 | D29: 7 | E29: 6 | F29: 2 | G29: 994 | H29: 3661 | I29: 7 | J29: 3 | K29: 0.444178 | L29: 0.725058 | M29: 6023 | N29: 6 | O29: 2 | P29: 7 | Q29: 0 | R29: =TEXT(A29,"yyyy-mm") -> 2026-09 | S29: =IF(K29="","",(L29-K29)*24) -> 6.74112 | T29: =IF(N29=0,"",M29/N29/60) -> 16.730556 | U29: =IF(E29=0,"",G29/E29) -> 165.66667 | V29: =IF(D29=0,"",E29/D29) -> 0.85714286
A30: 46267 | B30: 篠﨑 悠 | C30: 1 | D30: 41 | E30: 37 | F30: 22 | G30: 6816 | H30: 6816 | I30: 11 | J30: 11 | K30: 0.443056 | L30: 0.797708 | M30: 11964 | N30: 40 | O30: 1 | P30: 40 | Q30: 2 | R30: =TEXT(A30,"yyyy-mm") -> 2026-09 | S30: =IF(K30="","",(L30-K30)*24) -> 8.511648 | T30: =IF(N30=0,"",M30/N30/60) -> 4.985 | U30: =IF(E30=0,"",G30/E30) -> 184.21622 | V30: =IF(D30=0,"",E30/D30) -> 0.90243902
A31: 46268 | B31: 篠﨑 悠 | C31: 1 | D31: 0 | E31: 0 | F31: 0 | G31: 0 | H31: 0 | I31: 5 | J31: 5 | M31: 0 | N31: 0 | O31: 0 | P31: 0 | Q31: 0 | R31: =TEXT(A31,"yyyy-mm") -> 2026-09 | S31: =IF(K31="","",(L31-K31)*24) | T31: =IF(N31=0,"",M31/N31/60) | U31: =IF(E31=0,"",G31/E31) | V31: =IF(D31=0,"",E31/D31)
A32: 46269 | B32: 篠﨑 悠 | C32: 1 | D32: 38 | E32: 33 | F32: 18 | G32: 4784 | H32: 5471 | I32: 9 | J32: 6 | K32: 0.45456 | L32: 0.776285 | M32: 13580 | N32: 37 | O32: 2 | P32: 36 | Q32: 8 | R32: =TEXT(A32,"yyyy-mm") -> 2026-09 | S32: =IF(K32="","",(L32-K32)*24) -> 7.7214 | T32: =IF(N32=0,"",M32/N32/60) -> 6.1171171 | U32: =IF(E32=0,"",G32/E32) -> 144.9697 | V32: =IF(D32=0,"",E32/D32) -> 0.86842105
A33: 46272 | B33: 篠﨑 悠 | C33: 1 | D33: 30 | E33: 24 | F33: 14 | G33: 3686 | H33: 6806 | I33: 8 | J33: 5 | K33: 0.469699 | L33: 0.797153 | M33: 10584 | N33: 29 | O33: 2 | P33: 30 | Q33: 0 | R33: =TEXT(A33,"yyyy-mm") -> 2026-09 | S33: =IF(K33="","",(L33-K33)*24) -> 7.858896 | T33: =IF(N33=0,"",M33/N33/60) -> 6.0827586 | U33: =IF(E33=0,"",G33/E33) -> 153.58333 | V33: =IF(D33=0,"",E33/D33) -> 0.8
A34: 46273 | B34: 篠﨑 悠 | C34: 1 | D34: 37 | E34: 32 | F34: 20 | G34: 4880 | H34: 5722 | I34: 9 | J34: 4 | K34: 0.43022 | L34: 0.771505 | M34: 10699 | N34: 35 | O34: 3 | P34: 35 | Q34: 8 | R34: =TEXT(A34,"yyyy-mm") -> 2026-09 | S34: =IF(K34="","",(L34-K34)*24) -> 8.19084 | T34: =IF(N34=0,"",M34/N34/60) -> 5.0947619 | U34: =IF(E34=0,"",G34/E34) -> 152.5 | V34: =IF(D34=0,"",E34/D34) -> 0.86486486
A35: 46274 | B35: 篠﨑 悠 | C35: 1 | D35: 38 | E35: 29 | F35: 12 | G35: 5296 | H35: 7376 | I35: 14 | J35: 8 | K35: 0.43625 | L35: 0.748437 | M35: 9638 | N35: 35 | O35: 2 | P35: 35 | Q35: 20 | R35: =TEXT(A35,"yyyy-mm") -> 2026-09 | S35: =IF(K35="","",(L35-K35)*24) -> 7.492488 | T35: =IF(N35=0,"",M35/N35/60) -> 4.5895238 | U35: =IF(E35=0,"",G35/E35) -> 182.62069 | V35: =IF(D35=0,"",E35/D35) -> 0.76315789
A36: 46275 | B36: 篠﨑 悠 | C36: 1 | D36: 48 | E36: 40 | F36: 19 | G36: 5157 | H36: 5818 | I36: 10 | J36: 7 | K36: 0.448461 | L36: 0.819792 | M36: 15201 | N36: 46 | O36: 3 | P36: 41 | Q36: 20 | R36: =TEXT(A36,"yyyy-mm") -> 2026-09 | S36: =IF(K36="","",(L36-K36)*24) -> 8.911944 | T36: =IF(N36=0,"",M36/N36/60) -> 5.5076087 | U36: =IF(E36=0,"",G36/E36) -> 128.925 | V36: =IF(D36=0,"",E36/D36) -> 0.83333333
A37: 46276 | B37: 篠﨑 悠 | C37: 1 | D37: 36 | E37: 30 | F37: 11 | G37: 5261 | H37: 7878 | I37: 14 | J37: 10 | K37: 0.442627 | L37: 0.75037 | M37: 15759 | N37: 33 | O37: 2 | P37: 30 | Q37: 20 | R37: =TEXT(A37,"yyyy-mm") -> 2026-09 | S37: =IF(K37="","",(L37-K37)*24) -> 7.385832 | T37: =IF(N37=0,"",M37/N37/60) -> 7.9590909 | U37: =IF(E37=0,"",G37/E37) -> 175.36667 | V37: =IF(D37=0,"",E37/D37) -> 0.83333333
A38: 46277 | B38: 篠﨑 悠 | C38: 0 | D38: 0 | E38: 0 | F38: 0 | G38: 0 | H38: 0 | I38: 2 | J38: 2 | M38: 0 | N38: 0 | O38: 0 | P38: 0 | Q38: 0 | R38: =TEXT(A38,"yyyy-mm") -> 2026-09 | S38: =IF(K38="","",(L38-K38)*24) | T38: =IF(N38=0,"",M38/N38/60) | U38: =IF(E38=0,"",G38/E38) | V38: =IF(D38=0,"",E38/D38)
A39: 46235 | B39: 森 沙里菜 | C39: 0 | D39: 0 | E39: 0 | F39: 0 | G39: 0 | H39: 0 | I39: 2 | J39: 2 | M39: 0 | N39: 0 | O39: 0 | P39: 0 | Q39: 0 | R39: =TEXT(A39,"yyyy-mm") -> 2026-08 | S39: =IF(K39="","",(L39-K39)*24) | T39: =IF(N39=0,"",M39/N39/60) | U39: =IF(E39=0,"",G39/E39) | V39: =IF(D39=0,"",E39/D39)
A40: 46236 | B40: 森 沙里菜 | C40: 0 | D40: 0 | E40: 0 | F40: 0 | G40: 0 | H40: 0 | I40: 1 | J40: 1 | M40: 0 | N40: 0 | O40: 0 | P40: 0 | Q40: 0 | R40: =TEXT(A40,"yyyy-mm") -> 2026-08 | S40: =IF(K40="","",(L40-K40)*24) | T40: =IF(N40=0,"",M40/N40/60) | U40: =IF(E40=0,"",G40/E40) | V40: =IF(D40=0,"",E40/D40)
...

Sheet サマリ
A1: 架電活動サマリ（メンバー別・月別）
A2: 出所：zoomus_call_log_2026-09-14.csv（2026-08-01〜2026-09-13）／日次集計は「データ」シート
B3: 営業日数（土日祝除く） | D3: 2026-08 | E3: 20 | F3: 2026-09(1-13) | G3: 9
A4: ■ 2026年8月 | B4: 2026-08
A5: メンバー | B5: 実稼働日数 | C5: 営業日数 | D5: 架電数 | E5: 架電数/営業日 | F5: 架電数/稼働日 | G5: 接触数(接続) | H5: 接触数/営業日 | I5: 接触数/稼働日 | J5: 接続率 | K5: 平均通話時間(秒) | L5: 60秒以上率 | M5: 通話時間計(h) | N5: 通話時間/稼働日(h) | O5: 平均架電間隔(分) | P5: 30分超アイドル/日 | Q5: 稼働時間/日(h) | R5: 通話占有率 | S5: 着信数 | T5: 着信不在率 | U5: ユニーク架電先数(日次計) | V5: 再架電率
A6: 篠﨑 悠 | B6: =COUNTIFS(データ!$B:$B,$A6,データ!$R:$R,$B$4,データ!$D:$D,">0") -> 17 | C6: =$E$3 -> 20 | D6: =SUMIFS(データ!$D:$D,データ!$B:$B,$A6,データ!$R:$R,$B$4) -> 721 | E6: =D6/C6 -> 36.05 | F6: =D6/B6 -> 42.411765 | G6: =SUMIFS(データ!$E:$E,データ!$B:$B,$A6,データ!$R:$R,$B$4) -> 602 | H6: =G6/C6 -> 30.1 | I6: =G6/B6 -> 35.411765 | J6: =IFERROR(G6/D6,"") -> 0.83495146 | K6: =IFERROR(SUMIFS(データ!$G:$G,データ!$B:$B,$A6,データ!$R:$R,$B$4)/G6,"") -> 185.34219 | L6: =IFERROR(SUMIFS(データ!$F:$F,データ!$B:$B,$A6,データ!$R:$R,$B$4)/G6,"") -> 0.52657807 | M6: =SUMIFS(データ!$G:$G,データ!$B:$B,$A6,データ!$R:$R,$B$4)/3600 -> 30.993333 | N6: =M6/B6 -> 1.8231373 | O6: =IFERROR(SUMIFS(データ!$M:$M,データ!$B:$B,$A6,データ!$R:$R,$B$4)/SUMIFS(データ!$N:$N,データ!$B:$B,$A6,データ!$R:$R,$B$4)/60,"") -> 5.3314048 | P6: =SUMIFS(データ!$O:$O,データ!$B:$B,$A6,データ!$R:$R,$B$4)/B6 -> 2.1176471 | Q6: =IFERROR(AVERAGEIFS(データ!$S:$S,データ!$B:$B,$A6,データ!$R:$R,$B$4,データ!$D:$D,">0"),"") -> 7.9579567 | R6: =IFERROR(SUMIFS(データ!$H:$H,データ!$B:$B,$A6,データ!$R:$R,$B$4)/3600/B6/Q6,"") -> 0.27578351 | S6: =SUMIFS(データ!$I:$I,データ!$B:$B,$A6,データ!$R:$R,$B$4) -> 210 | T6: =IFERROR(SUMIFS(データ!$J:$J,データ!$B:$B,$A6,データ!$R:$R,$B$4)/S6,"") -> 0.67142857 | U6: =SUMIFS(データ!$P:$P,データ!$B:$B,$A6,データ!$R:$R,$B$4) -> 647 | V6: =IFERROR(SUMIFS(データ!$Q:$Q,データ!$B:$B,$A6,データ!$R:$R,$B$4)/D6,"") -> 0.42857143
A7: 森 沙里菜 | B7: =COUNTIFS(データ!$B:$B,$A7,データ!$R:$R,$B$4,データ!$D:$D,">0") -> 20 | C7: =$E$3 -> 20 | D7: =SUMIFS(データ!$D:$D,データ!$B:$B,$A7,データ!$R:$R,$B$4) -> 1130 | E7: =D7/C7 -> 56.5 | F7: =D7/B7 -> 56.5 | G7: =SUMIFS(データ!$E:$E,データ!$B:$B,$A7,データ!$R:$R,$B$4) -> 959 | H7: =G7/C7 -> 47.95 | I7: =G7/B7 -> 47.95 | J7: =IFERROR(G7/D7,"") -> 0.84867257 | K7: =IFERROR(SUMIFS(データ!$G:$G,データ!$B:$B,$A7,データ!$R:$R,$B$4)/G7,"") -> 214.53597 | L7: =IFERROR(SUMIFS(データ!$F:$F,データ!$B:$B,$A7,データ!$R:$R,$B$4)/G7,"") -> 0.55578728 | M7: =SUMIFS(データ!$G:$G,データ!$B:$B,$A7,データ!$R:$R,$B$4)/3600 -> 57.15 | N7: =M7/B7 -> 2.8575 | O7: =IFERROR(SUMIFS(データ!$M:$M,データ!$B:$B,$A7,データ!$R:$R,$B$4)/SUMIFS(データ!$N:$N,データ!$B:$B,$A7,データ!$R:$R,$B$4)/60,"") -> 4.1334835 | P7: =SUMIFS(データ!$O:$O,データ!$B:$B,$A7,データ!$R:$R,$B$4)/B7 -> 1.7 | Q7: =IFERROR(AVERAGEIFS(データ!$S:$S,データ!$B:$B,$A7,データ!$R:$R,$B$4,データ!$D:$D,">0"),"") -> 8.4233892 | R7: =IFERROR(SUMIFS(データ!$H:$H,データ!$B:$B,$A7,データ!$R:$R,$B$4)/3600/B7/Q7,"") -> 0.38886762 | S7: =SUMIFS(データ!$I:$I,データ!$B:$B,$A7,データ!$R:$R,$B$4) -> 258 | T7: =IFERROR(SUMIFS(データ!$J:$J,データ!$B:$B,$A7,データ!$R:$R,$B$4)/S7,"") -> 0.74031008 | U7: =SUMIFS(データ!$P:$P,データ!$B:$B,$A7,データ!$R:$R,$B$4) -> 986 | V7: =IFERROR(SUMIFS(データ!$Q:$Q,データ!$B:$B,$A7,データ!$R:$R,$B$4)/D7,"") -> 0.56283186
A8: 小泉 政貴 | B8: =COUNTIFS(データ!$B:$B,$A8,データ!$R:$R,$B$4,データ!$D:$D,">0") -> 20 | C8: =$E$3 -> 20 | D8: =SUMIFS(データ!$D:$D,データ!$B:$B,$A8,データ!$R:$R,$B$4) -> 760 | E8: =D8/C8 -> 38 | F8: =D8/B8 -> 38 | G8: =SUMIFS(データ!$E:$E,データ!$B:$B,$A8,データ!$R:$R,$B$4) -> 595 | H8: =G8/C8 -> 29.75 | I8: =G8/B8 -> 29.75 | J8: =IFERROR(G8/D8,"") -> 0.78289474 | K8: =IFERROR(SUMIFS(データ!$G:$G,データ!$B:$B,$A8,データ!$R:$R,$B$4)/G8,"") -> 199.53613 | L8: =IFERROR(SUMIFS(データ!$F:$F,データ!$B:$B,$A8,データ!$R:$R,$B$4)/G8,"") -> 0.50756303 | M8: =SUMIFS(データ!$G:$G,データ!$B:$B,$A8,データ!$R:$R,$B$4)/3600 -> 32.978889 | N8: =M8/B8 -> 1.6489444 | O8: =IFERROR(SUMIFS(データ!$M:$M,データ!$B:$B,$A8,データ!$R:$R,$B$4)/SUMIFS(データ!$N:$N,データ!$B:$B,$A8,データ!$R:$R,$B$4)/60,"") -> 6.3291667 | P8: =SUMIFS(データ!$O:$O,データ!$B:$B,$A8,データ!$R:$R,$B$4)/B8 -> 2.95 | Q8: =IFERROR(AVERAGEIFS(データ!$S:$S,データ!$B:$B,$A8,データ!$R:$R,$B$4,データ!$D:$D,">0"),"") -> 8.0062656 | R8: =IFERROR(SUMIFS(データ!$H:$H,データ!$B:$B,$A8,データ!$R:$R,$B$4)/3600/B8/Q8,"") -> 0.2429781 | S8: =SUMIFS(データ!$I:$I,データ!$B:$B,$A8,データ!$R:$R,$B$4) -> 183 | T8: =IFERROR(SUMIFS(データ!$J:$J,データ!$B:$B,$A8,データ!$R:$R,$B$4)/S8,"") -> 0.79781421 | U8: =SUMIFS(データ!$P:$P,データ!$B:$B,$A8,データ!$R:$R,$B$4) -> 640 | V8: =IFERROR(SUMIFS(データ!$Q:$Q,データ!$B:$B,$A8,データ!$R:$R,$B$4)/D8,"") -> 0.49078947
A9: 霜田 孝太郎 | B9: =COUNTIFS(データ!$B:$B,$A9,データ!$R:$R,$B$4,データ!$D:$D,">0") -> 24 | C9: =$E$3 -> 20 | D9: =SUMIFS(データ!$D:$D,データ!$B:$B,$A9,データ!$R:$R,$B$4) -> 889 | E9: =D9/C9 -> 44.45 | F9: =D9/B9 -> 37.041667 | G9: =SUMIFS(データ!$E:$E,データ!$B:$B,$A9,データ!$R:$R,$B$4) -> 713 | H9: =G9/C9 -> 35.65 | I9: =G9/B9 -> 29.708333 | J9: =IFERROR(G9/D9,"") -> 0.80202475 | K9: =IFERROR(SUMIFS(データ!$G:$G,データ!$B:$B,$A9,データ!$R:$R,$B$4)/G9,"") -> 184.63394 | L9: =IFERROR(SUMIFS(データ!$F:$F,データ!$B:$B,$A9,データ!$R:$R,$B$4)/G9,"") -> 0.54698457 | M9: =SUMIFS(データ!$G:$G,データ!$B:$B,$A9,データ!$R:$R,$B$4)/3600 -> 36.567778 | N9: =M9/B9 -> 1.5236574 | O9: =IFERROR(SUMIFS(データ!$M:$M,データ!$B:$B,$A9,データ!$R:$R,$B$4)/SUMIFS(データ!$N:$N,データ!$B:$B,$A9,データ!$R:$R,$B$4)/60,"") -> 4.4951569 | P9: =SUMIFS(データ!$O:$O,データ!$B:$B,$A9,データ!$R:$R,$B$4)/B9 -> 2.125 | Q9: =IFERROR(AVERAGEIFS(データ!$S:$S,データ!$B:$B,$A9,データ!$R:$R,$B$4,データ!$D:$D,">0"),"") -> 6.48934 | R9: =IFERROR(SUMIFS(データ!$H:$H,データ!$B:$B,$A9,データ!$R:$R,$B$4)/3600/B9/Q9,"") -> 0.25041067 | S9: =SUMIFS(データ!$I:$I,データ!$B:$B,$A9,データ!$R:$R,$B$4) -> 188 | T9: =IFERROR(SUMIFS(データ!$J:$J,データ!$B:$B,$A9,データ!$R:$R,$B$4)/S9,"") -> 0.87765957 | U9: =SUMIFS(データ!$P:$P,データ!$B:$B,$A9,データ!$R:$R,$B$4) -> 753 | V9: =IFERROR(SUMIFS(データ!$Q:$Q,データ!$B:$B,$A9,データ!$R:$R,$B$4)/D9,"") -> 0.47244094
A10: 高橋 采伽 | B10: =COUNTIFS(データ!$B:$B,$A10,データ!$R:$R,$B$4,データ!$D:$D,">0") -> 10 | C10: =$E$3 -> 20 | D10: =SUMIFS(データ!$D:$D,データ!$B:$B,$A10,データ!$R:$R,$B$4) -> 502 | E10: =D10/C10 -> 25.1 | F10: =D10/B10 -> 50.2 | G10: =SUMIFS(データ!$E:$E,データ!$B:$B,$A10,データ!$R:$R,$B$4) -> 379 | H10: =G10/C10 -> 18.95 | I10: =G10/B10 -> 37.9 | J10: =IFERROR(G10/D10,"") -> 0.75498008 | K10: =IFERROR(SUMIFS(データ!$G:$G,データ!$B:$B,$A10,データ!$R:$R,$B$4)/G10,"") -> 95.424802 | L10: =IFERROR(SUMIFS(データ!$F:$F,データ!$B:$B,$A10,データ!$R:$R,$B$4)/G10,"") -> 0.42216359 | M10: =SUMIFS(データ!$G:$G,データ!$B:$B,$A10,データ!$R:$R,$B$4)/3600 -> 10.046111 | N10: =M10/B10 -> 1.0046111 | O10: =IFERROR(SUMIFS(データ!$M:$M,データ!$B:$B,$A10,データ!$R:$R,$B$4)/SUMIFS(データ!$N:$N,データ!$B:$B,$A10,データ!$R:$R,$B$4)/60,"") -> 4.6187973 | P10: =SUMIFS(データ!$O:$O,データ!$B:$B,$A10,データ!$R:$R,$B$4)/B10 -> 2.1 | Q10: =IFERROR(AVERAGEIFS(データ!$S:$S,データ!$B:$B,$A10,データ!$R:$R,$B$4,データ!$D:$D,">0"),"") -> 7.0163016 | R10: =IFERROR(SUMIFS(データ!$H:$H,データ!$B:$B,$A10,データ!$R:$R,$B$4)/3600/B10/Q10,"") -> 0.15745475 | S10: =SUMIFS(データ!$I:$I,データ!$B:$B,$A10,データ!$R:$R,$B$4) -> 44 | T10: =IFERROR(SUMIFS(データ!$J:$J,データ!$B:$B,$A10,データ!$R:$R,$B$4)/S10,"") -> 0.56818182 | U10: =SUMIFS(データ!$P:$P,データ!$B:$B,$A10,データ!$R:$R,$B$4) -> 477 | V10: =IFERROR(SUMIFS(データ!$Q:$Q,データ!$B:$B,$A10,データ!$R:$R,$B$4)/D10,"") -> 0.33266932
A11: 和田 宗大 | B11: =COUNTIFS(データ!$B:$B,$A11,データ!$R:$R,$B$4,データ!$D:$D,">0") -> 13 | C11: =$E$3 -> 20 | D11: =SUMIFS(データ!$D:$D,データ!$B:$B,$A11,データ!$R:$R,$B$4) -> 825 | E11: =D11/C11 -> 41.25 | F11: =D11/B11 -> 63.461538 | G11: =SUMIFS(データ!$E:$E,データ!$B:$B,$A11,データ!$R:$R,$B$4) -> 632 | H11: =G11/C11 -> 31.6 | I11: =G11/B11 -> 48.615385 | J11: =IFERROR(G11/D11,"") -> 0.76606061 | K11: =IFERROR(SUMIFS(データ!$G:$G,データ!$B:$B,$A11,データ!$R:$R,$B$4)/G11,"") -> 94.068038 | L11: =IFERROR(SUMIFS(データ!$F:$F,データ!$B:$B,$A11,データ!$R:$R,$B$4)/G11,"") -> 0.41613924 | M11: =SUMIFS(データ!$G:$G,データ!$B:$B,$A11,データ!$R:$R,$B$4)/3600 -> 16.514167 | N11: =M11/B11 -> 1.2703205 | O11: =IFERROR(SUMIFS(データ!$M:$M,データ!$B:$B,$A11,データ!$R:$R,$B$4)/SUMIFS(データ!$N:$N,データ!$B:$B,$A11,データ!$R:$R,$B$4)/60,"") -> 3.3975539 | P11: =SUMIFS(データ!$O:$O,データ!$B:$B,$A11,データ!$R:$R,$B$4)/B11 -> 1.4615385 | Q11: =IFERROR(AVERAGEIFS(データ!$S:$S,データ!$B:$B,$A11,データ!$R:$R,$B$4,データ!$D:$D,">0"),"") -> 6.8861742 | R11: =IFERROR(SUMIFS(データ!$H:$H,データ!$B:$B,$A11,データ!$R:$R,$B$4)/3600/B11/Q11,"") -> 0.21792707 | S11: =SUMIFS(データ!$I:$I,データ!$B:$B,$A11,データ!$R:$R,$B$4) -> 76 | T11: =IFERROR(SUMIFS(データ!$J:$J,データ!$B:$B,$A11,データ!$R:$R,$B$4)/S11,"") -> 0.57894737 | U11: =SUMIFS(データ!$P:$P,データ!$B:$B,$A11,データ!$R:$R,$B$4) -> 743 | V11: =IFERROR(SUMIFS(データ!$Q:$Q,データ!$B:$B,$A11,データ!$R:$R,$B$4)/D11,"") -> 0.4630303
A13: ■ 2026年9月（1〜13日） | B13: 2026-09
A14: メンバー | B14: 実稼働日数 | C14: 営業日数 | D14: 架電数 | E14: 架電数/営業日 | F14: 架電数/稼働日 | G14: 接触数(接続) | H14: 接触数/営業日 | I14: 接触数/稼働日 | J14: 接続率 | K14: 平均通話時間(秒) | L14: 60秒以上率 | M14: 通話時間計(h) | N14: 通話時間/稼働日(h) | O14: 平均架電間隔(分) | P14: 30分超アイドル/日 | Q14: 稼働時間/日(h) | R14: 通話占有率 | S14: 着信数 | T14: 着信不在率 | U14: ユニーク架電先数(日次計) | V14: 再架電率
A15: 篠﨑 悠 | B15: =COUNTIFS(データ!$B:$B,$A15,データ!$R:$R,$B$13,データ!$D:$D,">0") -> 8 | C15: =$G$3 -> 9 | D15: =SUMIFS(データ!$D:$D,データ!$B:$B,$A15,データ!$R:$R,$B$13) -> 275 | E15: =D15/C15 -> 30.555556 | F15: =D15/B15 -> 34.375 | G15: =SUMIFS(データ!$E:$E,データ!$B:$B,$A15,データ!$R:$R,$B$13) -> 231 | H15: =G15/C15 -> 25.666667 | I15: =G15/B15 -> 28.875 | J15: =IFERROR(G15/D15,"") -> 0.84 | K15: =IFERROR(SUMIFS(データ!$G:$G,データ!$B:$B,$A15,データ!$R:$R,$B$13)/G15,"") -> 159.62771 | L15: =IFERROR(SUMIFS(データ!$F:$F,データ!$B:$B,$A15,データ!$R:$R,$B$13)/G15,"") -> 0.51082251 | M15: =SUMIFS(データ!$G:$G,データ!$B:$B,$A15,データ!$R:$R,$B$13)/3600 -> 10.242778 | N15: =M15/B15 -> 1.2803472 | O15: =IFERROR(SUMIFS(データ!$M:$M,データ!$B:$B,$A15,データ!$R:$R,$B$13)/SUMIFS(データ!$N:$N,データ!$B:$B,$A15,データ!$R:$R,$B$13)/60,"") -> 5.9673052 | P15: =SUMIFS(データ!$O:$O,データ!$B:$B,$A15,データ!$R:$R,$B$13)/B15 -> 2.125 | Q15: =IFERROR(AVERAGEIFS(データ!$S:$S,データ!$B:$B,$A15,データ!$R:$R,$B$13,データ!$D:$D,">0"),"") -> 7.851771 | R15: =IFERROR(SUMIFS(データ!$H:$H,データ!$B:$B,$A15,データ!$R:$R,$B$13)/3600/B15/Q15,"") -> 0.21911193 | S15: =SUMIFS(データ!$I:$I,データ!$B:$B,$A15,データ!$R:$R,$B$13) -> 89 | T15: =IFERROR(SUMIFS(データ!$J:$J,データ!$B:$B,$A15,データ!$R:$R,$B$13)/S15,"") -> 0.68539326 | U15: =SUMIFS(データ!$P:$P,データ!$B:$B,$A15,データ!$R:$R,$B$13) -> 254 | V15: =IFERROR(SUMIFS(データ!$Q:$Q,データ!$B:$B,$A15,データ!$R:$R,$B$13)/D15,"") -> 0.28363636
A16: 森 沙里菜 | B16: =COUNTIFS(データ!$B:$B,$A16,データ!$R:$R,$B$13,データ!$D:$D,">0") -> 9 | C16: =$G$3 -> 9 | D16: =SUMIFS(データ!$D:$D,データ!$B:$B,$A16,データ!$R:$R,$B$13) -> 465 | E16: =D16/C16 -> 51.666667 | F16: =D16/B16 -> 51.666667 | G16: =SUMIFS(データ!$E:$E,データ!$B:$B,$A16,データ!$R:$R,$B$13) -> 370 | H16: =G16/C16 -> 41.111111 | I16: =G16/B16 -> 41.111111 | J16: =IFERROR(G16/D16,"") -> 0.79569892 | K16: =IFERROR(SUMIFS(データ!$G:$G,データ!$B:$B,$A16,データ!$R:$R,$B$13)/G16,"") -> 202.53784 | L16: =IFERROR(SUMIFS(データ!$F:$F,データ!$B:$B,$A16,データ!$R:$R,$B$13)/G16,"") -> 0.57297297 | M16: =SUMIFS(データ!$G:$G,データ!$B:$B,$A16,データ!$R:$R,$B$13)/3600 -> 20.816389 | N16: =M16/B16 -> 2.3129321 | O16: =IFERROR(SUMIFS(データ!$M:$M,データ!$B:$B,$A16,データ!$R:$R,$B$13)/SUMIFS(データ!$N:$N,データ!$B:$B,$A16,データ!$R:$R,$B$13)/60,"") -> 5.3145602 | P16: =SUMIFS(データ!$O:$O,データ!$B:$B,$A16,データ!$R:$R,$B$13)/B16 -> 2.8888889 | Q16: =IFERROR(AVERAGEIFS(データ!$S:$S,データ!$B:$B,$A16,データ!$R:$R,$B$13,データ!$D:$D,">0"),"") -> 8.609472 | R16: =IFERROR(SUMIFS(データ!$H:$H,データ!$B:$B,$A16,データ!$R:$R,$B$13)/3600/B16/Q16,"") -> 0.2924105 | S16: =SUMIFS(データ!$I:$I,データ!$B:$B,$A16,データ!$R:$R,$B$13) -> 78 | T16: =IFERROR(SUMIFS(データ!$J:$J,データ!$B:$B,$A16,データ!$R:$R,$B$13)/S16,"") -> 0.79487179 | U16: =SUMIFS(データ!$P:$P,データ!$B:$B,$A16,データ!$R:$R,$B$13) -> 399 | V16: =IFERROR(SUMIFS(データ!$Q:$Q,データ!$B:$B,$A16,データ!$R:$R,$B$13)/D16,"") -> 0.50752688
A17: 小泉 政貴 | B17: =COUNTIFS(データ!$B:$B,$A17,データ!$R:$R,$B$13,データ!$D:$D,">0") -> 9 | C17: =$G$3 -> 9 | D17: =SUMIFS(データ!$D:$D,データ!$B:$B,$A17,データ!$R:$R,$B$13) -> 295 | E17: =D17/C17 -> 32.777778 | F17: =D17/B17 -> 32.777778 | G17: =SUMIFS(データ!$E:$E,データ!$B:$B,$A17,データ!$R:$R,$B$13) -> 248 | H17: =G17/C17 -> 27.555556 | I17: =G17/B17 -> 27.555556 | J17: =IFERROR(G17/D17,"") -> 0.84067797 | K17: =IFERROR(SUMIFS(データ!$G:$G,データ!$B:$B,$A17,データ!$R:$R,$B$13)/G17,"") -> 205.46371 | L17: =IFERROR(SUMIFS(データ!$F:$F,データ!$B:$B,$A17,データ!$R:$R,$B$13)/G17,"") -> 0.53629032 | M17: =SUMIFS(データ!$G:$G,データ!$B:$B,$A17,データ!$R:$R,$B$13)/3600 -> 14.154167 | N17: =M17/B17 -> 1.5726852 | O17: =IFERROR(SUMIFS(データ!$M:$M,データ!$B:$B,$A17,データ!$R:$R,$B$13)/SUMIFS(データ!$N:$N,データ!$B:$B,$A17,データ!$R:$R,$B$13)/60,"") -> 6.0654888 | P17: =SUMIFS(データ!$O:$O,データ!$B:$B,$A17,データ!$R:$R,$B$13)/B17 -> 2.2222222 | Q17: =IFERROR(AVERAGEIFS(データ!$S:$S,データ!$B:$B,$A17,データ!$R:$R,$B$13,データ!$D:$D,">0"),"") -> 6.8105173 | R17: =IFERROR(SUMIFS(データ!$H:$H,データ!$B:$B,$A17,データ!$R:$R,$B$13)/3600/B17/Q17,"") -> 0.25199315 | S17: =SUMIFS(データ!$I:$I,データ!$B:$B,$A17,データ!$R:$R,$B$13) -> 87 | T17: =IFERROR(SUMIFS(データ!$J:$J,データ!$B:$B,$A17,データ!$R:$R,$B$13)/S17,"") -> 0.83908046 | U17: =SUMIFS(データ!$P:$P,データ!$B:$B,$A17,データ!$R:$R,$B$13) -> 250 | V17: =IFERROR(SUMIFS(データ!$Q:$Q,データ!$B:$B,$A17,データ!$R:$R,$B$13)/D17,"") -> 0.37288136
A18: 霜田 孝太郎 | B18: =COUNTIFS(データ!$B:$B,$A18,データ!$R:$R,$B$13,データ!$D:$D,">0") -> 11 | C18: =$G$3 -> 9 | D18: =SUMIFS(データ!$D:$D,データ!$B:$B,$A18,データ!$R:$R,$B$13) -> 376 | E18: =D18/C18 -> 41.777778 | F18: =D18/B18 -> 34.181818 | G18: =SUMIFS(データ!$E:$E,データ!$B:$B,$A18,データ!$R:$R,$B$13) -> 304 | H18: =G18/C18 -> 33.777778 | I18: =G18/B18 -> 27.636364 | J18: =IFERROR(G18/D18,"") -> 0.80851064 | K18: =IFERROR(SUMIFS(データ!$G:$G,データ!$B:$B,$A18,データ!$R:$R,$B$13)/G18,"") -> 183.65132 | L18: =IFERROR(SUMIFS(データ!$F:$F,データ!$B:$B,$A18,データ!$R:$R,$B$13)/G18,"") -> 0.5 | M18: =SUMIFS(データ!$G:$G,データ!$B:$B,$A18,データ!$R:$R,$B$13)/3600 -> 15.508333 | N18: =M18/B18 -> 1.4098485 | O18: =IFERROR(SUMIFS(データ!$M:$M,データ!$B:$B,$A18,データ!$R:$R,$B$13)/SUMIFS(データ!$N:$N,データ!$B:$B,$A18,データ!$R:$R,$B$13)/60,"") -> 5.1303922 | P18: =SUMIFS(データ!$O:$O,データ!$B:$B,$A18,データ!$R:$R,$B$13)/B18 -> 2.0909091 | Q18: =IFERROR(AVERAGEIFS(データ!$S:$S,データ!$B:$B,$A18,データ!$R:$R,$B$13,データ!$D:$D,">0"),"") -> 6.2878036 | R18: =IFERROR(SUMIFS(データ!$H:$H,データ!$B:$B,$A18,データ!$R:$R,$B$13)/3600/B18/Q18,"") -> 0.22874169 | S18: =SUMIFS(データ!$I:$I,データ!$B:$B,$A18,データ!$R:$R,$B$13) -> 85 | T18: =IFERROR(SUMIFS(データ!$J:$J,データ!$B:$B,$A18,データ!$R:$R,$B$13)/S18,"") -> 0.92941176 | U18: =SUMIFS(データ!$P:$P,データ!$B:$B,$A18,データ!$R:$R,$B$13) -> 321 | V18: =IFERROR(SUMIFS(データ!$Q:$Q,データ!$B:$B,$A18,データ!$R:$R,$B$13)/D18,"") -> 0.34574468
A19: 高橋 采伽 | B19: =COUNTIFS(データ!$B:$B,$A19,データ!$R:$R,$B$13,データ!$D:$D,">0") -> 9 | C19: =$G$3 -> 9 | D19: =SUMIFS(データ!$D:$D,データ!$B:$B,$A19,データ!$R:$R,$B$13) -> 378 | E19: =D19/C19 -> 42 | F19: =D19/B19 -> 42 | G19: =SUMIFS(データ!$E:$E,データ!$B:$B,$A19,データ!$R:$R,$B$13) -> 294 | H19: =G19/C19 -> 32.666667 | I19: =G19/B19 -> 32.666667 | J19: =IFERROR(G19/D19,"") -> 0.77777778 | K19: =IFERROR(SUMIFS(データ!$G:$G,データ!$B:$B,$A19,データ!$R:$R,$B$13)/G19,"") -> 108.14286 | L19: =IFERROR(SUMIFS(データ!$F:$F,データ!$B:$B,$A19,データ!$R:$R,$B$13)/G19,"") -> 0.46258503 | M19: =SUMIFS(データ!$G:$G,データ!$B:$B,$A19,データ!$R:$R,$B$13)/3600 -> 8.8316667 | N19: =M19/B19 -> 0.9812963 | O19: =IFERROR(SUMIFS(データ!$M:$M,データ!$B:$B,$A19,データ!$R:$R,$B$13)/SUMIFS(データ!$N:$N,データ!$B:$B,$A19,データ!$R:$R,$B$13)/60,"") -> 5.2098255 | P19: =SUMIFS(データ!$O:$O,データ!$B:$B,$A19,データ!$R:$R,$B$13)/B19 -> 2.6666667 | Q19: =IFERROR(AVERAGEIFS(データ!$S:$S,データ!$B:$B,$A19,データ!$R:$R,$B$13,データ!$D:$D,">0"),"") -> 6.8588293 | R19: =IFERROR(SUMIFS(データ!$H:$H,データ!$B:$B,$A19,データ!$R:$R,$B$13)/3600/B19/Q19,"") -> 0.17433598 | S19: =SUMIFS(データ!$I:$I,データ!$B:$B,$A19,データ!$R:$R,$B$13) -> 50 | T19: =IFERROR(SUMIFS(データ!$J:$J,データ!$B:$B,$A19,データ!$R:$R,$B$13)/S19,"") -> 0.56 | U19: =SUMIFS(データ!$P:$P,データ!$B:$B,$A19,データ!$R:$R,$B$13) -> 356 | V19: =IFERROR(SUMIFS(データ!$Q:$Q,データ!$B:$B,$A19,データ!$R:$R,$B$13)/D19,"") -> 0.31216931
A20: 和田 宗大 | B20: =COUNTIFS(データ!$B:$B,$A20,データ!$R:$R,$B$13,データ!$D:$D,">0") -> 9 | C20: =$G$3 -> 9 | D20: =SUMIFS(データ!$D:$D,データ!$B:$B,$A20,データ!$R:$R,$B$13) -> 405 | E20: =D20/C20 -> 45 | F20: =D20/B20 -> 45 | G20: =SUMIFS(データ!$E:$E,データ!$B:$B,$A20,データ!$R:$R,$B$13) -> 320 | H20: =G20/C20 -> 35.555556 | I20: =G20/B20 -> 35.555556 | J20: =IFERROR(G20/D20,"") -> 0.79012346 | K20: =IFERROR(SUMIFS(データ!$G:$G,データ!$B:$B,$A20,データ!$R:$R,$B$13)/G20,"") -> 117.08125 | L20: =IFERROR(SUMIFS(データ!$F:$F,データ!$B:$B,$A20,データ!$R:$R,$B$13)/G20,"") -> 0.471875 | M20: =SUMIFS(データ!$G:$G,データ!$B:$B,$A20,データ!$R:$R,$B$13)/3600 -> 10.407222 | N20: =M20/B20 -> 1.156358 | O20: =IFERROR(SUMIFS(データ!$M:$M,データ!$B:$B,$A20,データ!$R:$R,$B$13)/SUMIFS(データ!$N:$N,データ!$B:$B,$A20,データ!$R:$R,$B$13)/60,"") -> 3.6069878 | P20: =SUMIFS(データ!$O:$O,データ!$B:$B,$A20,データ!$R:$R,$B$13)/B20 -> 2.1111111 | Q20: =IFERROR(AVERAGEIFS(データ!$S:$S,データ!$B:$B,$A20,データ!$R:$R,$B$13,データ!$D:$D,">0"),"") -> 6.8069227 | R20: =IFERROR(SUMIFS(データ!$H:$H,データ!$B:$B,$A20,データ!$R:$R,$B$13)/3600/B20/Q20,"") -> 0.21154027 | S20: =SUMIFS(データ!$I:$I,データ!$B:$B,$A20,データ!$R:$R,$B$13) -> 56 | T20: =IFERROR(SUMIFS(データ!$J:$J,データ!$B:$B,$A20,データ!$R:$R,$B$13)/S20,"") -> 0.5 | U20: =SUMIFS(データ!$P:$P,データ!$B:$B,$A20,データ!$R:$R,$B$13) -> 359 | V20: =IFERROR(SUMIFS(データ!$Q:$Q,データ!$B:$B,$A20,データ!$R:$R,$B$13)/D20,"") -> 0.34567901
A23: ■ 比較：1稼働日あたりの架電数・接触数
A24: メンバー | B24: 8月 架電/日 | C24: 9月 架電/日 | D24: 8月 接触/日 | E24: 9月 接触/日
A25: =A6 -> 篠﨑 悠 | B25: =F6 -> 42.411765 | C25: =F15 -> 34.375 | D25: =I6 -> 35.411765 | E25: =I15 -> 28.875
A26: =A7 -> 森 沙里菜 | B26: =F7 -> 56.5 | C26: =F16 -> 51.666667 | D26: =I7 -> 47.95 | E26: =I16 -> 41.111111
A27: =A8 -> 小泉 政貴 | B27: =F8 -> 38 | C27: =F17 -> 32.777778 | D27: =I8 -> 29.75 | E27: =I17 -> 27.555556
A28: =A9 -> 霜田 孝太郎 | B28: =F9 -> 37.041667 | C28: =F18 -> 34.181818 | D28: =I9 -> 29.708333 | E28: =I18 -> 27.636364
A29: =A10 -> 高橋 采伽 | B29: =F10 -> 50.2 | C29: =F19 -> 42 | D29: =I10 -> 37.9 | E29: =I19 -> 32.666667
A30: =A11 -> 和田 宗大 | B30: =F11 -> 63.461538 | C30: =F20 -> 45 | D30: =I11 -> 48.615385 | E30: =I20 -> 35.555556

Sheet 総評
A1: 総評：メンバーの行動量と効率の評価
A2: 対象：2026-08-01〜2026-09-13（Zoom Phone 発着信ログ）。数値は「サマリ」シートを参照。
A4: Ⅰ. チーム全体の結論
A5: ① 「行動しているか」→ 量は出ている。稼働日あたり33〜52件の架電、接続率75〜85%と高水準。ただし9月は全员2026年8月比で1日あたり架電数が減少（△7〜19%）。
A6: ② 「無駄がないか」→ 最大のロスは「通話と通話の間」。稼働時間（その日の初回架電〜最終終話）に対する通話占有率は8月16〜39%、9月17〜29%。つまり1日約6〜9時間のうち、実際に話しているのは1.0〜2.9時間。残りは架電間隔と後処理に消えている。
A7: ③ 平均架電間隔は3.6〜6.1分（9月）。和田さんの3.6分がチーム最短、小泉・篠屎さんは6分超。差の2〜2.5分×40件＝1日約1.5〜1.7時間の差になる。後処理（記録・次リスト探し）の標準化が最優先の改善テーマ。
A8: ④ 30分超の空白（アイドル）が1日平均2〜3回。休憩・会議で説明できる範囲か、手が止まっているかを本人に確認する価値あり。
A9: ⑤ 着信（折返し含む）の不在率が67〜88%。こちらからの架電は頃合いにやっている一方で、相手からの着信を取り切れていない。最も欲しいリードを取りこぼしている可能性が高い。
A10: ⑥ 月内の同一番号への再架電率は17〜51%とバラツキが大きい。計画的な追客なのか、同じ先を無計画に掛け直しているのか、リスト供給量と照らして見る必要がある。
A12: Ⅱ. メンバー別評価（数値行は「サマリ」シートと連動）
A13: =サマリ!A6 -> 篠﨑 悠
A14: ="▶ 8月 "&TEXT(サマリ!F6,"0.0")&"件/稼働日 → 9月 "&TEXT(サマリ!F15,"0.0")&"件｜接触 "&TEXT(サマリ!I6,"0.0")&"→"&TEXT(サマリ!I15,"0.0")&"件｜接続率 "&TEXT(サマリ!J15,"0%")&"｜平均通話 "&TEXT(サマリ!K15,"0")&"秒｜架電間隔 "&TEXT(サマリ!O15,"0.0")&"分｜通話占有率 "&TEXT(サマリ!R15,"0%")&"｜稼働日 "&サマリ!B6&"/"&サマリ!C6&"日（9月 "&サマリ!B15&"/"&サマリ!C15&"日）" -> ▶ 8月 42.4件/稼働日 → 9月 34.4件｜接触 35.4→28.9件｜接続率 84%｜平均通話 160秒｜架電間隔 6.0分｜通話占有率 22%｜稼働日 17/20日（9月 8/9日）
A15: ○ 良い点：接続率84%・60秒以上通話51%と、架電の質はチーム上位。会話に持ち込めている。稼働時間（8時間/日）も長い。
A16: △ 課題：（1）9月に1日あたりの量が約19%落ちている（42.4→34.4件）。（2）架電間隔6.0分はチーム最長クラス。後処理を通話中に終わらせる運用に変えれば、1日+5〜8件は稼げる。（3）着信不在率69%。
A17: =サマリ!A7 -> 森 沙里菜
A18: ="▶ 8月 "&TEXT(サマリ!F7,"0.0")&"件/稼働日 → 9月 "&TEXT(サマリ!F16,"0.0")&"件｜接触 "&TEXT(サマリ!I7,"0.0")&"→"&TEXT(サマリ!I16,"0.0")&"件｜接続率 "&TEXT(サマリ!J16,"0%")&"｜平均通話 "&TEXT(サマリ!K16,"0")&"秒｜架電間隔 "&TEXT(サマリ!O16,"0.0")&"分｜通話占有率 "&TEXT(サマリ!R16,"0%")&"｜稼働日 "&サマリ!B7&"/"&サマリ!C7&"日（9月 "&サマリ!B16&"/"&サマリ!C16&"日）" -> ▶ 8月 56.5件/稼働日 → 9月 51.7件｜接触 48.0→41.1件｜接続率 80%｜平均通話 203秒｜架電間隔 5.3分｜通話占有率 29%｜稼働日 20/20日（9月 9/9日）
A19: ○ 良い点：行動量・会話量ともにチーム最高。稼働日は20/20日と欠けがなく、1日の通話時間も2.3〜2.9時間（占有率29%）で最大。チームの基準値にしてよい水準。
A20: △ 課題：再架電率51%（チーム最高）。同一番号への掛け直しが半分を占めるため、新規先のカバレッジが伸びないリスク。リスト供給が足りているか確認。着信不在率79%も高い。
A21: =サマリ!A8 -> 小泉 政貴
A22: ="▶ 8月 "&TEXT(サマリ!F8,"0.0")&"件/稼働日 → 9月 "&TEXT(サマリ!F17,"0.0")&"件｜接触 "&TEXT(サマリ!I8,"0.0")&"→"&TEXT(サマリ!I17,"0.0")&"件｜接続率 "&TEXT(サマリ!J17,"0%")&"｜平均通話 "&TEXT(サマリ!K17,"0")&"秒｜架電間隔 "&TEXT(サマリ!O17,"0.0")&"分｜通話占有率 "&TEXT(サマリ!R17,"0%")&"｜稼働日 "&サマリ!B8&"/"&サマリ!C8&"日（9月 "&サマリ!B17&"/"&サマリ!C17&"日）" -> ▶ 8月 38.0件/稼働日 → 9月 32.8件｜接触 29.8→27.6件｜接続率 84%｜平均通話 205秒｜架電間隔 6.1分｜通話占有率 25%｜稼働日 20/20日（9月 9/9日）
A23: ○ 良い点：1件あたりの平均通話が205秒でチーム最長。接続後にきちんと会話を作れている。稼働日は欠けなし（20/20日）。
A24: △ 課題：（1）架電間隔6.1分でチーム最長、架電数は32.8件/日で下位。「丁寧だがテンポが遅い」典型。長電話後のリカバリー時間を計る価値あり。（2）着信不在率84%（183件中146件不在/8月）で折返しを取れていない。
A25: =サマリ!A9 -> 霜田 孝太郎
A26: ="▶ 8月 "&TEXT(サマリ!F9,"0.0")&"件/稼働日 → 9月 "&TEXT(サマリ!F18,"0.0")&"件｜接触 "&TEXT(サマリ!I9,"0.0")&"→"&TEXT(サマリ!I18,"0.0")&"件｜接続率 "&TEXT(サマリ!J18,"0%")&"｜平均通話 "&TEXT(サマリ!K18,"0")&"秒｜架電間隔 "&TEXT(サマリ!O18,"0.0")&"分｜通話占有率 "&TEXT(サマリ!R18,"0%")&"｜稼働日 "&サマリ!B9&"/"&サマリ!C9&"日（9月 "&サマリ!B18&"/"&サマリ!C18&"日）" -> ▶ 8月 37.0件/稼働日 → 9月 34.2件｜接触 29.7→27.6件｜接続率 81%｜平均通話 184秒｜架電間隔 5.1分｜通話占有率 23%｜稼働日 24/20日（9月 11/9日）
A27: ○ 良い点：架電間隔5.1分・平均通話184秒でバランス良好。土日（8/8、8/22、8/29、9/5、9/13）も架電しており稼働日数が最多（営業日20日に対し発信日24日）。
A28: △ 課題：（1）稼働時間（初回〜最終）6.3時間で最短、初回架電が平均11:45と遅い。午前の稼働が薄い。（2）通話失敗が8月71件と他メンバーの2〜4倍。番号リストの品質か発信環境を確認。（3）着信不在率88%でチーム最悪。（4）土日稼働は成果が伴っているか検証必要（土日の架電は1日1〜30件と少ない）。
A29: =サマリ!A10 -> 高橋 采伽
A30: ="▶ 8月 "&TEXT(サマリ!F10,"0.0")&"件/稼働日 → 9月 "&TEXT(サマリ!F19,"0.0")&"件｜接触 "&TEXT(サマリ!I10,"0.0")&"→"&TEXT(サマリ!I19,"0.0")&"件｜接続率 "&TEXT(サマリ!J19,"0%")&"｜平均通話 "&TEXT(サマリ!K19,"0")&"秒｜架電間隔 "&TEXT(サマリ!O19,"0.0")&"分｜通話占有率 "&TEXT(サマリ!R19,"0%")&"｜稼働日 "&サマリ!B10&"/"&サマリ!C10&"日（9月 "&サマリ!B19&"/"&サマリ!C19&"日）" -> ▶ 8月 50.2件/稼働日 → 9月 42.0件｜接触 37.9→32.7件｜接続率 78%｜平均通話 108秒｜架電間隔 5.2分｜通話占有率 17%｜稼働日 10/20日（9月 9/9日）
A31: ○ 良い点：8/18からの稼働開始ですぐに42〜50件/日に到達。量をこなす姿勢は十分。接続率を78%まで上げている。
A32: △ 課題：平均通話108秒、通話占有率17%ともにチーム最低。「掛けているが話せていない」状態で、量を減らしてもトーク（受付突破・ヒアリング）のロールプレイに時間を割く方がリターンが大きい。伸びしろは最大。
A33: =サマリ!A11 -> 和田 宗大
A34: ="▶ 8月 "&TEXT(サマリ!F11,"0.0")&"件/稼働日 → 9月 "&TEXT(サマリ!F20,"0.0")&"件｜接触 "&TEXT(サマリ!I11,"0.0")&"→"&TEXT(サマリ!I20,"0.0")&"件｜接続率 "&TEXT(サマリ!J20,"0%")&"｜平均通話 "&TEXT(サマリ!K20,"0")&"秒｜架電間隔 "&TEXT(サマリ!O20,"0.0")&"分｜通話占有率 "&TEXT(サマリ!R20,"0%")&"｜稼働日 "&サマリ!B11&"/"&サマリ!C11&"日（9月 "&サマリ!B20&"/"&サマリ!C20&"日）" -> ▶ 8月 63.5件/稼働日 → 9月 45.0件｜接触 48.6→35.6件｜接続率 79%｜平均通話 117秒｜架電間隔 3.6分｜通話占有率 21%｜稼働日 13/20日（9月 9/9日）
A35: ○ 良い点：架電間隔3.6分でチーム最短。次の電話への切り替えが最も速く、行動テンポのお手本。架電数を45〜63件/日と上位。
A36: △ 課題：（1）平均通話117秒、8月は接続済み632件のうち179件（28%）が10秒未満。形式上の「接触」にカウントされているだけで、実質の会話になっていない可能性が高い（名乗り直後の切られ・自動応答など）。（2）稼働日が8月13日/20営業日（発信開始は8/7）。不在日の理由を確認。
A38: Ⅲ. 提言（優先順）
A39: 1）架電間隔をKPIに追加する。4分以内を目標にすると、小泉・篠屎・森で日あたり+5〜10件の余地がある（間隔2分短紩×40件＝約1.3時間/日）。
A40: 2）接触の定義を「接続済み」から「接続済みかつ30秒以上」に変える。現在の接続済みには10秒未満の瞬間切れが全体て13%、和田さんで28%含まれる。
A41: 3）着信の取得率を上げる。不在率67〜88%は明らかな機会損失。ハントグループでの相互カバー、または折返し時間帯（多くは架電直後）の席外しを禁止。
A42: 4）午前の稼働を揃える。初回架電の平均は10:05〜11:45と最大1時間半の差。朝一の架電開始時刻をチームで統一するだけで日数分の差が埋まる。
A43: 5）再架電ルールを明文化する（例：不在は時間帯を変えて最大3回/月まで）。再架電率17〜51%のバラツキは、ルール不在のサイン。
...

Sheet Data Sources
A1: Written to | B1: Source | C1: Object | D1: Obtained via | E1: Query or request | F1: Run at | G1: Row count | H1: Notes
A2: データ!A1:Q209 | B2: アップロードファイル | C2: zoomus_call_log_2026-09-14.csv | D2: Uploaded file | E2: 添付CSVからメンバー別の月別架電数・接触数（営業日ベース／1日あたり）、平均通話時間、架電間隔、総評を出力 | F2: 46279 | G2: 208 | H2: 1コール2行の重複行（番号列が空）を除外し9,408コールへ整理。うち対象6名分8,425コールをメンバー×日で集計。
